Workbook
Name row_filter: #REF!

Sheet Instructions
A1: VOLTAIC x KOVAAKS BENCHMARKS - SEASON 4
A2: How this sheet works
A3: Edit this sheet by going to File → Make a copy. If the sheet says it is outdated, simply head over to the resources channel and make a new copy.
A4: Our benchmarks are divided in 3 levels: Novice, Intermediate and Advanced
A5: New players should play the Novice benchmarks
A6: Guideline: Aspiring Platinum players are recommended to achieve Gold on Novice to be able to move on to the Intermediate benchmarks
A7: Guideline: Aspiring Grandmaster players are recommended to achieve Master on Intermediate to be able to move on to the Advanced benchmarks
A8: In order to receive a rank you need to set a score on a scenario from each of the six subcategories (Dynamic, Static, Precise, Reactive, Speed and Evasive)
A9: Only your highest score in a subcategory will count towards your rank
A10: Your overall energy is an average of your subcategory energy, with lower scores weighted more heavily (harmonic mean)
A11: Pushing your score further to the next rank target awards more energy
A12: This allows you to acquire ranks without being equally skilled in each aiming subcategory
... A14: The chart below shows the energy required for each rank
A15: Difficulty | B15: Click to navigate to the Novice Benchmarks | F15: Click to navigate to the Intermediate Benchmarks | J15: Click to navigate to the Advanced Benchmarks
B16: Novice | F16: Intermediate | J16: Advanced
A17: Rank Name | B17: =IFERROR(__xludf.DUMMYFUNCTION("importrange(""https://docs.google.com/spreadsheets/d/10ck-sXoSgAYeiVI9iaaWwSqxC7KoxNO-2AtO08C-eCw"", ""Benchmarks!D3:G4"")"),"Iron") -> Iron | C17: =IFERROR(__xludf.DUMMYFUNCTION("""COMPUTED_VALUE"""),"Bronze") -> Bronze | D17: =IFERROR(__xludf.DUMMYFUNCTION("""COMPUTED_VALUE"""),"Silver") -> Silver | E17: =IFERROR(__xludf.DUMMYFUNCTION("""COMPUTED_VALUE"""),"Gold") -> Gold | F17: =IFERROR(__xludf.DUMMYFUNCTION("importrange(""https://docs.google.com/spreadsheets/d/10ck-sXoSgAYeiVI9iaaWwSqxC7KoxNO-2AtO08C-eCw"", ""Benchmarks!K3:N4"")"),"Platinum") -> Platinum | G17: =IFERROR(__xludf.DUMMYFUNCTION("""COMPUTED_VALUE"""),"Diamond") -> Diamond | H17: =IFERROR(__xludf.DUMMYFUNCTION("""COMPUTED_VALUE"""),"Jade") -> Jade | I17: =IFERROR(__xludf.DUMMYFUNCTION("""COMPUTED_VALUE"""),"Master") -> Master | J17: =IFERROR(__xludf.DUMMYFUNCTION("importrange(""https://docs.google.com/spreadsheets/d/10ck-sXoSgAYeiVI9iaaWwSqxC7KoxNO-2AtO08C-eCw"", ""Benchmarks!R3:U4"")"),"Grandmaster") -> Grandmaster | K17: =IFERROR(__xludf.DUMMYFUNCTION("""COMPUTED_VALUE"""),"Nova") -> Nova | L17: =IFERROR(__xludf.DUMMYFUNCTION("""COMPUTED_VALUE"""),"Astra") -> Astra | M17: =IFERROR(__xludf.DUMMYFUNCTION("""COMPUTED_VALUE"""),"Celestial") -> Celestial
A18: Energy Threshold | B18: =IFERROR(__xludf.DUMMYFUNCTION("""COMPUTED_VALUE"""),100.0) -> 100 | C18: =IFERROR(__xludf.DUMMYFUNCTION("""COMPUTED_VALUE"""),200.0) -> 200 | D18: =IFERROR(__xludf.DUMMYFUNCTION("""COMPUTED_VALUE"""),300.0) -> 300 | E18: =IFERROR(__xludf.DUMMYFUNCTION("""COMPUTED_VALUE"""),400.0) -> 400 | F18: =IFERROR(__xludf.DUMMYFUNCTION("""COMPUTED_VALUE"""),500.0) -> 500 | G18: =IFERROR(__xludf.DUMMYFUNCTION("""COMPUTED_VALUE"""),600.0) -> 600 | H18: =IFERROR(__xludf.DUMMYFUNCTION("""COMPUTED_VALUE"""),700.0) -> 700 | I18: =IFERROR(__xludf.DUMMYFUNCTION("""COMPUTED_VALUE"""),800.0) -> 800 | J18: =IFERROR(__xludf.DUMMYFUNCTION("""COMPUTED_VALUE"""),900.0) -> 900 | K18: =IFERROR(__xludf.DUMMYFUNCTION("""COMPUTED_VALUE"""),1000.0) -> 1000 | L18: =IFERROR(__xludf.DUMMYFUNCTION("""COMPUTED_VALUE"""),1100.0) -> 1100 | M18: =IFERROR(__xludf.DUMMYFUNCTION("""COMPUTED_VALUE"""),1200.0) -> 1200
A19: =IFERROR(__xludf.DUMMYFUNCTION("if(importrange(""https://docs.google.com/spreadsheets/d/1qUzF2KHcfs_FgsaDFRfGsLgHhoC1Md5bzMOUbsYzSjg"", ""Changelog!A2:A2"")=indirect(""Changelog!A2""), concatenate(""Sheet Version: "", Changelog!A2), hyperlink(""https://docs.google.com/spreadsheets/d/1qU"&"zF2KHcfs_FgsaDFRfGsLgHhoC1Md5bzMOUbsYzSjg"", ""Outdated version, click link & make a new copy!""))"),"Sheet Version: 1.2.9") -> Sheet Version: 1.2.9
A20: Socials | B20: =HYPERLINK("https://voltaic.gg/", "Website↗") -> Website↗ | D20: =HYPERLINK("http://discord.gg/voltaic","Discord↗") -> Discord↗ | F20: Twitter↗ | H20: YouTube↗ | J20: =HYPERLINK("https://bit.ly/VTxKvKsGuide","Guide↗") -> Guide↗ | L20: =HYPERLINK("https://docs.google.com/document/d/1omExq_y4ld9vkvbTFkLdjlT5UwQpvYSgyk5PgA7nrzM/edit?usp=sharing","Rules↗") -> Rules↗

Sheet Novice
A1: Voltaic KvKs Novice Benchmarks S4 | D1: {=concatenate(choose(match(G2, {0, L2:O2}), "Unranked", L1, M1, N1, O1), if(and(E3:E14 >= choose(match(G2, {0, L2:O2}), 1E+99, L3:L14, M3:M14, N3:N14, O3:O14)), " Complete", ""))} -> Unranked | G1: Energy | H1: {=concatenate(choose(match(K2, {0, L2:O2}), "Unranked", L1, M1, N1, O1), if(and(I3:I14 >= choose(match(K2, {0, L2:O2}), 1E+99, L3:L14, M3:M14, N3:N14, O3:O14)), " Complete", ""))} -> Unranked | K1: Energy | L1: =IFERROR(__xludf.DUMMYFUNCTION("importrange(""https://docs.google.com/spreadsheets/d/10ck-sXoSgAYeiVI9iaaWwSqxC7KoxNO-2AtO08C-eCw"", ""Benchmarks!D3:G16"")"),"Iron") -> Iron | M1: =IFERROR(__xludf.DUMMYFUNCTION("""COMPUTED_VALUE"""),"Bronze") -> Bronze | N1: =IFERROR(__xludf.DUMMYFUNCTION("""COMPUTED_VALUE"""),"Silver") -> Silver | O1: =IFERROR(__xludf.DUMMYFUNCTION("""COMPUTED_VALUE"""),"Gold") -> Gold | P1: Instructions
C2: Scenario | E2: High Score | F2: Progress | G2: =iferror(trunc(harmean(G3:G13)), 0) -> 0 | I2: Avg Score | J2: Progress | K2: =iferror(trunc(harmean(K3:K13)), 0) -> 0 | L2: =IFERROR(__xludf.DUMMYFUNCTION("""COMPUTED_VALUE"""),100.0) -> 100 | M2: =IFERROR(__xludf.DUMMYFUNCTION("""COMPUTED_VALUE"""),200.0) -> 200 | N2: =IFERROR(__xludf.DUMMYFUNCTION("""COMPUTED_VALUE"""),300.0) -> 300 | O2: =IFERROR(__xludf.DUMMYFUNCTION("""COMPUTED_VALUE"""),400.0) -> 400 | P2: Meet the energy threshold to obtain your desired rank
A3: Clicking | B3: Dynamic | C3: =IFERROR(__xludf.DUMMYFUNCTION("importrange(""https://docs.google.com/spreadsheets/d/10ck-sXoSgAYeiVI9iaaWwSqxC7KoxNO-2AtO08C-eCw/"", ""Benchmarks!C5:C18"")")," VT Pasu Rasp Novice") -> VT Pasu Rasp Novice | F3: =IFERROR(__xludf.DUMMYFUNCTION("sparkline( E3 - choose(match(E3, {0, L3:O3}), 0, L3, M3, N3, O3), { ""charttype"", ""bar""; ""max"", choose(match(E3, {0, L3:O3}), L3, M3-L3, N3-M3, O3-N3, 0); ""nan"", ""ignore""; ""color1"", iferror(choose(match(E3, {0, L3:O3}), "&" ""#999999"", ""#ff9900"", ""#cbd9e6"", ""#cab148"", ""#e5d9b4"" )) } ) "),"") | G3: {=trunc(min(Intermediate!L$2, max( choose(match(E3, {0, L3:O3}), 0, L$2, M$2, N$2, O$2) + (E3 - choose(match(E3, {0, L3:O3}), 0, L3, M3, N3, O3)) / choose(match(E3, {0, L3:O3}), L3, M3-L3, N3-M3, O3-N3, O3-N3) * choose(match(E3, {0, L3:O3}), L$2, M$2-L$2, N$2-M$2, O$2-N$2, O$2-N$2), choose(match(E4, {0, L4:O4}), 0, L$2, M$2, N$2, O$2) + (E4 - choose(match(E4, {0, L4:O4}), 0, L4, M4, N4, O4)) / choose(match(E4, {0, L4:O4}), L4, M4-L4, N4-M4, O4-N4, O4-N4) * choose(match(E4, {0, L4:O4}), L$2, M$2-L$2, N$2-M$2, O$2-N$2, O$2-N$2) )))} -> 0 | I3: ='Average Input'!D39 | J3: =IFERROR(__xludf.DUMMYFUNCTION("sparkline( I3 - choose(match(I3, {0, L3:O3}), 0, L3, M3, N3, O3), { ""charttype"", ""bar""; ""max"", choose(match(I3, {0, L3:O3}), L3, M3-L3, N3-M3, O3-N3, 0); ""nan"", ""ignore""; ""color1"", iferror(choose(match(I3, {0, L3:O3}), "&" ""#999999"", ""#ff9900"", ""#cbd9e6"", ""#cab148"", ""#e5d9b4"" )) } ) "),"") | K3: {=trunc(min(Intermediate!L$2, max( choose(match(I3, {0, L3:O3}), 0, L$2, M$2, N$2, O$2) + (I3 - choose(match(I3, {0, L3:O3}), 0, L3, M3, N3, O3)) / choose(match(I3, {0, L3:O3}), L3, M3-L3, N3-M3, O3-N3, O3-N3) * choose(match(I3, {0, L3:O3}), L$2, M$2-L$2, N$2-M$2, O$2-N$2, O$2-N$2), choose(match(I4, {0, L4:O4}), 0, L$2, M$2, N$2, O$2) + (I4 - choose(match(I4, {0, L4:O4}), 0, L4, M4, N4, O4)) / choose(match(I4, {0, L4:O4}), L4, M4-L4, N4-M4, O4-N4, O4-N4) * choose(match(I4, {0, L4:O4}), L$2, M$2-L$2, N$2-M$2, O$2-N$2, O$2-N$2) )))} -> 0 | L3: =IFERROR(__xludf.DUMMYFUNCTION("""COMPUTED_VALUE"""),550.0) -> 550 | M3: =IFERROR(__xludf.DUMMYFUNCTION("""COMPUTED_VALUE"""),650.0) -> 650 | N3: =IFERROR(__xludf.DUMMYFUNCTION("""COMPUTED_VALUE"""),750.0) -> 750 | O3: =IFERROR(__xludf.DUMMYFUNCTION("""COMPUTED_VALUE"""),850.0) -> 850 | P3: Each subcategory awards points based on your highest achieved rank threshold
C4: =IFERROR(__xludf.DUMMYFUNCTION("""COMPUTED_VALUE""")," VT Bounceshot Novice") -> VT Bounceshot Novice | F4: =IFERROR(__xludf.DUMMYFUNCTION("sparkline( E4 - choose(match(E4, {0, L4:O4}), 0, L4, M4, N4, O4), { ""charttype"", ""bar""; ""max"", choose(match(E4, {0, L4:O4}), L4, M4-L4, N4-M4, O4-N4, 0); ""nan"", ""ignore""; ""color1"", iferror(choose(match(E4, {0, L4:O4}), "&" ""#999999"", ""#ff9900"", ""#cbd9e6"", ""#cab148"", ""#e5d9b4"" )) } ) "),"") | I4: ='Average Input'!D40 | J4: =IFERROR(__xludf.DUMMYFUNCTION("sparkline( I4 - choose(match(I4, {0, L4:O4}), 0, L4, M4, N4, O4), { ""charttype"", ""bar""; ""max"", choose(match(I4, {0, L4:O4}), L4, M4-L4, N4-M4, O4-N4, 0); ""nan"", ""ignore""; ""color1"", iferror(choose(match(I4, {0, L4:O4}), "&" ""#999999"", ""#ff9900"", ""#cbd9e6"", ""#cab148"", ""#e5d9b4"" )) } ) "),"") | L4: =IFERROR(__xludf.DUMMYFUNCTION("""COMPUTED_VALUE"""),500.0) -> 500 | M4: =IFERROR(__xludf.DUMMYFUNCTION("""COMPUTED_VALUE"""),600.0) -> 600 | N4: =IFERROR(__xludf.DUMMYFUNCTION("""COMPUTED_VALUE"""),700.0) -> 700 | O4: =IFERROR(__xludf.DUMMYFUNCTION("""COMPUTED_VALUE"""),800.0) -> 800
B5: Static | C5: =IFERROR(__xludf.DUMMYFUNCTION("""COMPUTED_VALUE""")," VT 1w6ts Rasp Novice") -> VT 1w6ts Rasp Novice | F5: =IFERROR(__xludf.DUMMYFUNCTION("sparkline( E5 - choose(match(E5, {0, L5:O5}), 0, L5, M5, N5, O5), { ""charttype"", ""bar""; ""max"", choose(match(E5, {0, L5:O5}), L5, M5-L5, N5-M5, O5-N5, 0); ""nan"", ""ignore""; ""color1"", iferror(choose(match(E5, {0, L5:O5}), "&" ""#999999"", ""#ff9900"", ""#cbd9e6"", ""#cab148"", ""#e5d9b4"" )) } ) "),"") | G5: {=trunc(min(Intermediate!L$2, max( choose(match(E5, {0, L5:O5}), 0, L$2, M$2, N$2, O$2) + (E5 - choose(match(E5, {0, L5:O5}), 0, L5, M5, N5, O5)) / choose(match(E5, {0, L5:O5}), L5, M5-L5, N5-M5, O5-N5, O5-N5) * choose(match(E5, {0, L5:O5}), L$2, M$2-L$2, N$2-M$2, O$2-N$2, O$2-N$2), choose(match(E6, {0, L6:O6}), 0, L$2, M$2, N$2, O$2) + (E6 - choose(match(E6, {0, L6:O6}), 0, L6, M6, N6, O6)) / choose(match(E6, {0, L6:O6}), L6, M6-L6, N6-M6, O6-N6, O6-N6) * choose(match(E6, {0, L6:O6}), L$2, M$2-L$2, N$2-M$2, O$2-N$2, O$2-N$2) )))} -> 0 | I5: ='Average Input'!D41 | J5: =IFERROR(__xludf.DUMMYFUNCTION("sparkline( I5 - choose(match(I5, {0, L5:O5}), 0, L5, M5, N5, O5), { ""charttype"", ""bar""; ""max"", choose(match(I5, {0, L5:O5}), L5, M5-L5, N5-M5, O5-N5, 0); ""nan"", ""ignore""; ""color1"", iferror(choose(match(I5, {0, L5:O5}), "&" ""#999999"", ""#ff9900"", ""#cbd9e6"", ""#cab148"", ""#e5d9b4"" )) } ) "),"") | K5: {=trunc(min(Intermediate!L$2, max( choose(match(I5, {0, L5:O5}), 0, L$2, M$2, N$2, O$2) + (I5 - choose(match(I5, {0, L5:O5}), 0, L5, M5, N5, O5)) / choose(match(I5, {0, L5:O5}), L5, M5-L5, N5-M5, O5-N5, O5-N5) * choose(match(I5, {0, L5:O5}), L$2, M$2-L$2, N$2-M$2, O$2-N$2, O$2-N$2), choose(match(I6, {0, L6:O6}), 0, L$2, M$2, N$2, O$2) + (I6 - choose(match(I6, {0, L6:O6}), 0, L6, M6, N6, O6)) / choose(match(I6, {0, L6:O6}), L6, M6-L6, N6-M6, O6-N6, O6-N6) * choose(match(I6, {0, L6:O6}), L$2, M$2-L$2, N$2-M$2, O$2-N$2, O$2-N$2) )))} -> 0 | L5: =IFERROR(__xludf.DUMMYFUNCTION("""COMPUTED_VALUE"""),650.0) -> 650 | M5: =IFERROR(__xludf.DUMMYFUNCTION("""COMPUTED_VALUE"""),750.0) -> 750 | N5: =IFERROR(__xludf.DUMMYFUNCTION("""COMPUTED_VALUE"""),850.0) -> 850 | O5: =IFERROR(__xludf.DUMMYFUNCTION("""COMPUTED_VALUE"""),950.0) -> 950 | P5: Only one score from each subcategory counts
C6: =IFERROR(__xludf.DUMMYFUNCTION("""COMPUTED_VALUE""")," VT Multiclick 120 Novice") -> VT Multiclick 120 Novice | F6: =IFERROR(__xludf.DUMMYFUNCTION("sparkline( E6 - choose(match(E6, {0, L6:O6}), 0, L6, M6, N6, O6), { ""charttype"", ""bar""; ""max"", choose(match(E6, {0, L6:O6}), L6, M6-L6, N6-M6, O6-N6, 0); ""nan"", ""ignore""; ""color1"", iferror(choose(match(E6, {0, L6:O6}), "&" ""#999999"", ""#ff9900"", ""#cbd9e6"", ""#cab148"", ""#e5d9b4"" )) } ) "),"") | I6: ='Average Input'!D42 | J6: =IFERROR(__xludf.DUMMYFUNCTION("sparkline( I6 - choose(match(I6, {0, L6:O6}), 0, L6, M6, N6, O6), { ""charttype"", ""bar""; ""max"", choose(match(I6, {0, L6:O6}), L6, M6-L6, N6-M6, O6-N6, 0); ""nan"", ""ignore""; ""color1"", iferror(choose(match(I6, {0, L6:O6}), "&" ""#999999"", ""#ff9900"", ""#cbd9e6"", ""#cab148"", ""#e5d9b4"" )) } ) "),"") | L6: =IFERROR(__xludf.DUMMYFUNCTION("""COMPUTED_VALUE"""),1160.0) -> 1160 | M6: =IFERROR(__xludf.DUMMYFUNCTION("""COMPUTED_VALUE"""),1260.0) -> 1260 | N6: =IFERROR(__xludf.DUMMYFUNCTION("""COMPUTED_VALUE"""),1360.0) -> 1360 | O6: =IFERROR(__xludf.DUMMYFUNCTION("""COMPUTED_VALUE"""),1460.0) -> 1460
A7: Tracking | B7: Precise | C7: =IFERROR(__xludf.DUMMYFUNCTION("""COMPUTED_VALUE""")," VT Smoothbot Novice") -> VT Smoothbot Novice | F7: =IFERROR(__xludf.DUMMYFUNCTION("sparkline( E7 - choose(match(E7, {0, L7:O7}), 0, L7, M7, N7, O7), { ""charttype"", ""bar""; ""max"", choose(match(E7, {0, L7:O7}), L7, M7-L7, N7-M7, O7-N7, 0); ""nan"", ""ignore""; ""color1"", iferror(choose(match(E7, {0, L7:O7}), "&" ""#999999"", ""#ff9900"", ""#cbd9e6"", ""#cab148"", ""#e5d9b4"" )) } ) "),"") | G7: {=trunc(min(Intermediate!L$2, max( choose(match(E7, {0, L7:O7}), 0, L$2, M$2, N$2, O$2) + (E7 - choose(match(E7, {0, L7:O7}), 0, L7, M7, N7, O7)) / choose(match(E7, {0, L7:O7}), L7, M7-L7, N7-M7, O7-N7, O7-N7) * choose(match(E7, {0, L7:O7}), L$2, M$2-L$2, N$2-M$2, O$2-N$2, O$2-N$2), choose(match(E8, {0, L8:O8}), 0, L$2, M$2, N$2, O$2) + (E8 - choose(match(E8, {0, L8:O8}), 0, L8, M8, N8, O8)) / choose(match(E8, {0, L8:O8}), L8, M8-L8, N8-M8, O8-N8, O8-N8) * choose(match(E8, {0, L8:O8}), L$2, M$2-L$2, N$2-M$2, O$2-N$2, O$2-N$2) )))} -> 0 | I7: ='Average Input'!D43 | J7: =IFERROR(__xludf.DUMMYFUNCTION("sparkline( I7 - choose(match(I7, {0, L7:O7}), 0, L7, M7, N7, O7), { ""charttype"", ""bar""; ""max"", choose(match(I7, {0, L7:O7}), L7, M7-L7, N7-M7, O7-N7, 0); ""nan"", ""ignore""; ""color1"", iferror(choose(match(I7, {0, L7:O7}), "&" ""#999999"", ""#ff9900"", ""#cbd9e6"", ""#cab148"", ""#e5d9b4"" )) } ) "),"") | K7: {=trunc(min(Intermediate!L$2, max( choose(match(I7, {0, L7:O7}), 0, L$2, M$2, N$2, O$2) + (I7 - choose(match(I7, {0, L7:O7}), 0, L7, M7, N7, O7)) / choose(match(I7, {0, L7:O7}), L7, M7-L7, N7-M7, O7-N7, O7-N7) * choose(match(I7, {0, L7:O7}), L$2, M$2-L$2, N$2-M$2, O$2-N$2, O$2-N$2), choose(match(I8, {0, L8:O8}), 0, L$2, M$2, N$2, O$2) + (I8 - choose(match(I8, {0, L8:O8}), 0, L8, M8, N8, O8)) / choose(match(I8, {0, L8:O8}), L8, M8-L8, N8-M8, O8-N8, O8-N8) * choose(match(I8, {0, L8:O8}), L$2, M$2-L$2, N$2-M$2, O$2-N$2, O$2-N$2) )))} -> 0 | L7: =IFERROR(__xludf.DUMMYFUNCTION("""COMPUTED_VALUE"""),2300.0) -> 2300 | M7: =IFERROR(__xludf.DUMMYFUNCTION("""COMPUTED_VALUE"""),2500.0) -> 2500 | N7: =IFERROR(__xludf.DUMMYFUNCTION("""COMPUTED_VALUE"""),3100.0) -> 3100 | O7: =IFERROR(__xludf.DUMMYFUNCTION("""COMPUTED_VALUE"""),3500.0) -> 3500 | P7: All your energy combined defines your final rank
C8: =IFERROR(__xludf.DUMMYFUNCTION("""COMPUTED_VALUE""")," VT PreciseOrb Novice") -> VT PreciseOrb Novice | F8: =IFERROR(__xludf.DUMMYFUNCTION("sparkline( E8 - choose(match(E8, {0, L8:O8}), 0, L8, M8, N8, O8), { ""charttype"", ""bar""; ""max"", choose(match(E8, {0, L8:O8}), L8, M8-L8, N8-M8, O8-N8, 0); ""nan"", ""ignore""; ""color1"", iferror(choose(match(E8, {0, L8:O8}), "&" ""#999999"", ""#ff9900"", ""#cbd9e6"", ""#cab148"", ""#e5d9b4"" )) } ) "),"") | I8: ='Average Input'!D44 | J8: =IFERROR(__xludf.DUMMYFUNCTION("sparkline( I8 - choose(match(I8, {0, L8:O8}), 0, L8, M8, N8, O8), { ""charttype"", ""bar""; ""max"", choose(match(I8, {0, L8:O8}), L8, M8-L8, N8-M8, O8-N8, 0); ""nan"", ""ignore""; ""color1"", iferror(choose(match(I8, {0, L8:O8}), "&" ""#999999"", ""#ff9900"", ""#cbd9e6"", ""#cab148"", ""#e5d9b4"" )) } ) "),"") | L8: =IFERROR(__xludf.DUMMYFUNCTION("""COMPUTED_VALUE"""),1300.0) -> 1300 | M8: =IFERROR(__xludf.DUMMYFUNCTION("""COMPUTED_VALUE"""),1600.0) -> 1600 | N8: =IFERROR(__xludf.DUMMYFUNCTION("""COMPUTED_VALUE"""),1900.0) -> 1900 | O8: =IFERROR(__xludf.DUMMYFUNCTION("""COMPUTED_VALUE"""),2200.0) -> 2200
B9: Reactive | C9: =IFERROR(__xludf.DUMMYFUNCTION("""COMPUTED_VALUE""")," VT Plaza Novice") -> VT Plaza Novice | F9: =IFERROR(__xludf.DUMMYFUNCTION("sparkline( E9 - choose(match(E9, {0, L9:O9}), 0, L9, M9, N9, O9), { ""charttype"", ""bar""; ""max"", choose(match(E9, {0, L9:O9}), L9, M9-L9, N9-M9, O9-N9, 0); ""nan"", ""ignore""; ""color1"", iferror(choose(match(E9, {0, L9:O9}), "&" ""#999999"", ""#ff9900"", ""#cbd9e6"", ""#cab148"", ""#e5d9b4"" )) } ) "),"") | G9: {=trunc(min(Intermediate!L$2, max( choose(match(E9, {0, L9:O9}), 0, L$2, M$2, N$2, O$2) + (E9 - choose(match(E9, {0, L9:O9}), 0, L9, M9, N9, O9)) / choose(match(E9, {0, L9:O9}), L9, M9-L9, N9-M9, O9-N9, O9-N9) * choose(match(E9, {0, L9:O9}), L$2, M$2-L$2, N$2-M$2, O$2-N$2, O$2-N$2), choose(match(E10, {0, L10:O10}), 0, L$2, M$2, N$2, O$2) + (E10 - choose(match(E10, {0, L10:O10}), 0, L10, M10, N10, O10)) / choose(match(E10, {0, L10:O10}), L10, M10-L10, N10-M10, O10-N10, O10-N10) * choose(match(E10, {0, L10:O10}), L$2, M$2-L$2, N$2-M$2, O$2-N$2, O$2-N$2) )))} -> 0 | I9: ='Average Input'!D45 | J9: =IFERROR(__xludf.DUMMYFUNCTION("sparkline( I9 - choose(match(I9, {0, L9:O9}), 0, L9, M9, N9, O9), { ""charttype"", ""bar""; ""max"", choose(match(I9, {0, L9:O9}), L9, M9-L9, N9-M9, O9-N9, 0); ""nan"", ""ignore""; ""color1"", iferror(choose(match(I9, {0, L9:O9}), "&" ""#999999"", ""#ff9900"", ""#cbd9e6"", ""#cab148"", ""#e5d9b4"" )) } ) "),"") | K9: {=trunc(min(Intermediate!L$2, max( choose(match(I9, {0, L9:O9}), 0, L$2, M$2, N$2, O$2) + (I9 - choose(match(I9, {0, L9:O9}), 0, L9, M9, N9, O9)) / choose(match(I9, {0, L9:O9}), L9, M9-L9, N9-M9, O9-N9, O9-N9) * choose(match(I9, {0, L9:O9}), L$2, M$2-L$2, N$2-M$2, O$2-N$2, O$2-N$2), choose(match(I10, {0, L10:O10}), 0, L$2, M$2, N$2, O$2) + (I10 - choose(match(I10, {0, L10:O10}), 0, L10, M10, N10, O10)) / choose(match(I10, {0, L10:O10}), L10, M10-L10, N10-M10, O10-N10, O10-N10) * choose(match(I10, {0, L10:O10}), L$2, M$2-L$2, N$2-M$2, O$2-N$2, O$2-N$2) )))} -> 0 | L9: =IFERROR(__xludf.DUMMYFUNCTION("""COMPUTED_VALUE"""),2150.0) -> 2150 | M9: =IFERROR(__xludf.DUMMYFUNCTION("""COMPUTED_VALUE"""),2450.0) -> 2450 | N9: =IFERROR(__xludf.DUMMYFUNCTION("""COMPUTED_VALUE"""),2850.0) -> 2850 | O9: =IFERROR(__xludf.DUMMYFUNCTION("""COMPUTED_VALUE"""),3050.0) -> 3050 | P9: Pushing your score further awards more Energy
C10: =IFERROR(__xludf.DUMMYFUNCTION("""COMPUTED_VALUE""")," VT Air Novice") -> VT Air Novice | F10: =IFERROR(__xludf.DUMMYFUNCTION("sparkline( E10 - choose(match(E10, {0, L10:O10}), 0, L10, M10, N10, O10), { ""charttype"", ""bar""; ""max"", choose(match(E10, {0, L10:O10}), L10, M10-L10, N10-M10, O10-N10, 0); ""nan"", ""ignore""; ""color1"", iferror(choose(match"&"(E10, {0, L10:O10}), ""#999999"", ""#ff9900"", ""#cbd9e6"", ""#cab148"", ""#e5d9b4"" )) } ) "),"") | I10: ='Average Input'!D46 | J10: =IFERROR(__xludf.DUMMYFUNCTION("sparkline( I10 - choose(match(I10, {0, L10:O10}), 0, L10, M10, N10, O10), { ""charttype"", ""bar""; ""max"", choose(match(I10, {0, L10:O10}), L10, M10-L10, N10-M10, O10-N10, 0); ""nan"", ""ignore""; ""color1"", iferror(choose(match"&"(I10, {0, L10:O10}), ""#999999"", ""#ff9900"", ""#cbd9e6"", ""#cab148"", ""#e5d9b4"" )) } ) "),"") | L10: =IFERROR(__xludf.DUMMYFUNCTION("""COMPUTED_VALUE"""),1900.0) -> 1900 | M10: =IFERROR(__xludf.DUMMYFUNCTION("""COMPUTED_VALUE"""),2200.0) -> 2200 | N10: =IFERROR(__xludf.DUMMYFUNCTION("""COMPUTED_VALUE"""),2500.0) -> 2500 | O10: =IFERROR(__xludf.DUMMYFUNCTION("""COMPUTED_VALUE"""),2800.0) -> 2800
A11: Switching | B11: Speed | C11: =IFERROR(__xludf.DUMMYFUNCTION("""COMPUTED_VALUE""")," VT psalmTS Novice") -> VT psalmTS Novice | F11: =IFERROR(__xludf.DUMMYFUNCTION("sparkline( E11 - choose(match(E11, {0, L11:O11}), 0, L11, M11, N11, O11), { ""charttype"", ""bar""; ""max"", choose(match(E11, {0, L11:O11}), L11, M11-L11, N11-M11, O11-N11, 0); ""nan"", ""ignore""; ""color1"", iferror(choose(match"&"(E11, {0, L11:O11}), ""#999999"", ""#ff9900"", ""#cbd9e6"", ""#cab148"", ""#e5d9b4"" )) } ) "),"") | G11: {=trunc(min(Intermediate!L$2, max( choose(match(E11, {0, L11:O11}), 0, L$2, M$2, N$2, O$2) + (E11 - choose(match(E11, {0, L11:O11}), 0, L11, M11, N11, O11)) / choose(match(E11, {0, L11:O11}), L11, M11-L11, N11-M11, O11-N11, O11-N11) * choose(match(E11, {0, L11:O11}), L$2, M$2-L$2, N$2-M$2, O$2-N$2, O$2-N$2), choose(match(E12, {0, L12:O12}), 0, L$2, M$2, N$2, O$2) + (E12 - choose(match(E12, {0, L12:O12}), 0, L12, M12, N12, O12)) / choose(match(E12, {0, L12:O12}), L12, M12-L12, N12-M12, O12-N12, O12-N12) * choose(match(E12, {0, L12:O12}), L$2, M$2-L$2, N$2-M$2, O$2-N$2, O$2-N$2) )))} -> 0 | I11: ='Average Input'!D47 | J11: =IFERROR(__xludf.DUMMYFUNCTION("sparkline( I11 - choose(match(I11, {0, L11:O11}), 0, L11, M11, N11, O11), { ""charttype"", ""bar""; ""max"", choose(match(I11, {0, L11:O11}), L11, M11-L11, N11-M11, O11-N11, 0); ""nan"", ""ignore""; ""color1"", iferror(choose(match"&"(I11, {0, L11:O11}), ""#999999"", ""#ff9900"", ""#cbd9e6"", ""#cab148"", ""#e5d9b4"" )) } ) "),"") | K11: {=trunc(min(Intermediate!L$2, max( choose(match(I11, {0, L11:O11}), 0, L$2, M$2, N$2, O$2) + (I11 - choose(match(I11, {0, L11:O11}), 0, L11, M11, N11, O11)) / choose(match(I11, {0, L11:O11}), L11, M11-L11, N11-M11, O11-N11, O11-N11) * choose(match(I11, {0, L11:O11}), L$2, M$2-L$2, N$2-M$2, O$2-N$2, O$2-N$2), choose(match(I12, {0, L12:O12}), 0, L$2, M$2, N$2, O$2) + (I12 - choose(match(I12, {0, L12:O12}), 0, L12, M12, N12, O12)) / choose(match(I12, {0, L12:O12}), L12, M12-L12, N12-M12, O12-N12, O12-N12) * choose(match(I12, {0, L12:O12}), L$2, M$2-L$2, N$2-M$2, O$2-N$2, O$2-N$2) )))} -> 0 | L11: =IFERROR(__xludf.DUMMYFUNCTION("""COMPUTED_VALUE"""),620.0) -> 620 | M11: =IFERROR(__xludf.DUMMYFUNCTION("""COMPUTED_VALUE"""),690.0) -> 690 | N11: =IFERROR(__xludf.DUMMYFUNCTION("""COMPUTED_VALUE"""),760.0) -> 760 | O11: =IFERROR(__xludf.DUMMYFUNCTION("""COMPUTED_VALUE"""),830.0) -> 830 | P11: This allows you to obtain ranks without having to be equally good in each subcategory
C12: =IFERROR(__xludf.DUMMYFUNCTION("""COMPUTED_VALUE""")," VT skyTS Novice") -> VT skyTS Novice | F12: =IFERROR(__xludf.DUMMYFUNCTION("sparkline( E12 - choose(match(E12, {0, L12:O12}), 0, L12, M12, N12, O12), { ""charttype"", ""bar""; ""max"", choose(match(E12, {0, L12:O12}), L12, M12-L12, N12-M12, O12-N12, 0); ""nan"", ""ignore""; ""color1"", iferror(choose(match"&"(E12, {0, L12:O12}), ""#999999"", ""#ff9900"", ""#cbd9e6"", ""#cab148"", ""#e5d9b4"" )) } ) "),"") | I12: ='Average Input'!D48 | J12: =IFERROR(__xludf.DUMMYFUNCTION("sparkline( I12 - choose(match(I12, {0, L12:O12}), 0, L12, M12, N12, O12), { ""charttype"", ""bar""; ""max"", choose(match(I12, {0, L12:O12}), L12, M12-L12, N12-M12, O12-N12, 0); ""nan"", ""ignore""; ""color1"", iferror(choose(match"&"(I12, {0, L12:O12}), ""#999999"", ""#ff9900"", ""#cbd9e6"", ""#cab148"", ""#e5d9b4"" )) } ) "),"") | L12: =IFERROR(__xludf.DUMMYFUNCTION("""COMPUTED_VALUE"""),780.0) -> 780 | M12: =IFERROR(__xludf.DUMMYFUNCTION("""COMPUTED_VALUE"""),860.0) -> 860 | N12: =IFERROR(__xludf.DUMMYFUNCTION("""COMPUTED_VALUE"""),950.0) -> 950 | O12: =IFERROR(__xludf.DUMMYFUNCTION("""COMPUTED_VALUE"""),1040.0) -> 1040
B13: Evasive | C13: =IFERROR(__xludf.DUMMYFUNCTION("""COMPUTED_VALUE""")," VT evaTS Novice") -> VT evaTS Novice | F13: =IFERROR(__xludf.DUMMYFUNCTION("sparkline( E13 - choose(match(E13, {0, L13:O13}), 0, L13, M13, N13, O13), { ""charttype"", ""bar""; ""max"", choose(match(E13, {0, L13:O13}), L13, M13-L13, N13-M13, O13-N13, 0); ""nan"", ""ignore""; ""color1"", iferror(choose(match"&"(E13, {0, L13:O13}), ""#999999"", ""#ff9900"", ""#cbd9e6"", ""#cab148"", ""#e5d9b4"" )) } ) "),"") | G13: {=trunc(min(Intermediate!L$2, max( choose(match(E13, {0, L13:O13}), 0, L$2, M$2, N$2, O$2) + (E13 - choose(match(E13, {0, L13:O13}), 0, L13, M13, N13, O13)) / choose(match(E13, {0, L13:O13}), L13, M13-L13, N13-M13, O13-N13, O13-N13) * choose(match(E13, {0, L13:O13}), L$2, M$2-L$2, N$2-M$2, O$2-N$2, O$2-N$2), choose(match(E14, {0, L14:O14}), 0, L$2, M$2, N$2, O$2) + (E14 - choose(match(E14, {0, L14:O14}), 0, L14, M14, N14, O14)) / choose(match(E14, {0, L14:O14}), L14, M14-L14, N14-M14, O14-N14, O14-N14) * choose(match(E14, {0, L14:O14}), L$2, M$2-L$2, N$2-M$2, O$2-N$2, O$2-N$2) )))} -> 0 | I13: ='Average Input'!D49 | J13: =IFERROR(__xludf.DUMMYFUNCTION("sparkline( I13 - choose(match(I13, {0, L13:O13}), 0, L13, M13, N13, O13), { ""charttype"", ""bar""; ""max"", choose(match(I13, {0, L13:O13}), L13, M13-L13, N13-M13, O13-N13, 0); ""nan"", ""ignore""; ""color1"", iferror(choose(match"&"(I13, {0, L13:O13}), ""#999999"", ""#ff9900"", ""#cbd9e6"", ""#cab148"", ""#e5d9b4"" )) } ) "),"") | K13: {=trunc(min(Intermediate!L$2, max( choose(match(I13, {0, L13:O13}), 0, L$2, M$2, N$2, O$2) + (I13 - choose(match(I13, {0, L13:O13}), 0, L13, M13, N13, O13)) / choose(match(I13, {0, L13:O13}), L13, M13-L13, N13-M13, O13-N13, O13-N13) * choose(match(I13, {0, L13:O13}), L$2, M$2-L$2, N$2-M$2, O$2-N$2, O$2-N$2), choose(match(I14, {0, L14:O14}), 0, L$2, M$2, N$2, O$2) + (I14 - choose(match(I14, {0, L14:O14}), 0, L14, M14, N14, O14)) / choose(match(I14, {0, L14:O14}), L14, M14-L14, N14-M14, O14-N14, O14-N14) * choose(match(I14, {0, L14:O14}), L$2, M$2-L$2, N$2-M$2, O$2-N$2, O$2-N$2) )))} -> 0 | L13: =IFERROR(__xludf.DUMMYFUNCTION("""COMPUTED_VALUE"""),450.0) -> 450 | M13: =IFERROR(__xludf.DUMMYFUNCTION("""COMPUTED_VALUE"""),510.0) -> 510 | N13: =IFERROR(__xludf.DUMMYFUNCTION("""COMPUTED_VALUE"""),560.0) -> 560 | O13: =IFERROR(__xludf.DUMMYFUNCTION("""COMPUTED_VALUE"""),620.0) -> 620 | P13: Simply search the scenario name in the browser to play the scenarios. Playlists coming soon.
C14: =IFERROR(__xludf.DUMMYFUNCTION("""COMPUTED_VALUE""")," VT bounceTS Novice") -> VT bounceTS Novice | F14: =IFERROR(__xludf.DUMMYFUNCTION("sparkline( E14 - choose(match(E14, {0, L14:O14}), 0, L14, M14, N14, O14), { ""charttype"", ""bar""; ""max"", choose(match(E14, {0, L14:O14}), L14, M14-L14, N14-M14, O14-N14, 0); ""nan"", ""ignore""; ""color1"", iferror(choose(match"&"(E14, {0, L14:O14}), ""#999999"", ""#ff9900"", ""#cbd9e6"", ""#cab148"", ""#e5d9b4"" )) } ) "),"") | I14: ='Average Input'!D50 | J14: =IFERROR(__xludf.DUMMYFUNCTION("sparkline( I14 - choose(match(I14, {0, L14:O14}), 0, L14, M14, N14, O14), { ""charttype"", ""bar""; ""max"", choose(match(I14, {0, L14:O14}), L14, M14-L14, N14-M14, O14-N14, 0); ""nan"", ""ignore""; ""color1"", iferror(choose(match"&"(I14, {0, L14:O14}), ""#999999"", ""#ff9900"", ""#cbd9e6"", ""#cab148"", ""#e5d9b4"" )) } ) "),"") | L14: =IFERROR(__xludf.DUMMYFUNCTION("""COMPUTED_VALUE"""),490.0) -> 490 | M14: =IFERROR(__xludf.DUMMYFUNCTION("""COMPUTED_VALUE"""),550.0) -> 550 | N14: =IFERROR(__xludf.DUMMYFUNCTION("""COMPUTED_VALUE"""),610.0) -> 610 | O14: =IFERROR(__xludf.DUMMYFUNCTION("""COMPUTED_VALUE"""),680.0) -> 680
A15: Sharecode | F15: =IFERROR(__xludf.DUMMYFUNCTION("if(importrange(""https://docs.google.com/spreadsheets/d/1qUzF2KHcfs_FgsaDFRfGsLgHhoC1Md5bzMOUbsYzSjg"", ""Changelog!A2:A2"")=indirect(""Changelog!A2""), concatenate(""Sheet Version: "", Changelog!A2), hyperlink(""https://docs.google.com/spreadsheets/d/1qU"&"zF2KHcfs_FgsaDFRfGsLgHhoC1Md5bzMOUbsYzSjg"", ""Outdated version, click link & make a new copy!""))"),"Sheet Version: 1.2.9") -> Sheet Version: 1.2.9 | M15: =HYPERLINK("https://voltaic.gg/", "Website↗") -> Website↗ | N15: =HYPERLINK("http://discord.gg/voltaic","Discord↗") -> Discord↗ | O15: =HYPERLINK("http://twitter.com/voltaichq","Twitter↗") -> Twitter↗ | P15: Troubleshooting
A16: KovaaKsClearingPetulantScoutrifle | P16: Reload workshop if a scenario doesn't show up in the workshop.
A17: Find more resources in discord.gg/voltaic | M17: =HYPERLINK("https://www.youtube.com/voltaichq","YouTube↗") -> YouTube↗ | N17: =HYPERLINK("https://bit.ly/VTxKvKsGuide","Guide↗") -> Guide↗ | O17: =HYPERLINK("https://docs.google.com/document/d/1omExq_y4ld9vkvbTFkLdjlT5UwQpvYSgyk5PgA7nrzM/edit?usp=sharing","Rules↗") -> Rules↗ | P17: Report bugs in the KovaaKs discord.
P18: Let us know via the v-feedback form if there are any bugs that Voltaic can fix.

Sheet Intermediate
A1: Voltaic KvKs Intermediate Benchmarks S4 | D1: {=concatenate(choose(match(G2, {0, L2:O2}), "Unranked", L1, M1, N1, O1), if(and(E3:E18 >= choose(match(G2, {0, L2:O2}), 1E+99, L3:L18, M3:M18, N3:N18, O3:O18)), " Complete", ""))} -> Unranked | G1: Energy | H1: {=concatenate(choose(match(K2, {0, L2:O2}), "Unranked", L1, M1, N1, O1), if(and(I3:I18 >= choose(match(G2, {0, L2:O2}), 1E+99, L3:L18, M3:M18, N3:N18, O3:O18)), " Complete", ""))} -> Unranked | K1: Energy | L1: =IFERROR(__xludf.DUMMYFUNCTION("importrange(""https://docs.google.com/spreadsheets/d/10ck-sXoSgAYeiVI9iaaWwSqxC7KoxNO-2AtO08C-eCw"", ""Benchmarks!K3:N20"")"),"Platinum") -> Platinum | M1: =IFERROR(__xludf.DUMMYFUNCTION("""COMPUTED_VALUE"""),"Diamond") -> Diamond | N1: =IFERROR(__xludf.DUMMYFUNCTION("""COMPUTED_VALUE"""),"Jade") -> Jade | O1: =IFERROR(__xludf.DUMMYFUNCTION("""COMPUTED_VALUE"""),"Master") -> Master | P1: Instructions | Q1: Strafe scenarios instructions
C2: Scenario | E2: High Score | F2: Progress | G2: =iferror(trunc(harmean(G3:G18)), 0) -> 0 | I2: Avg Score | J2: Progress | K2: =iferror(trunc(harmean(K3:K18)), 0) -> 0 | L2: =IFERROR(__xludf.DUMMYFUNCTION("""COMPUTED_VALUE"""),500.0) -> 500 | M2: =IFERROR(__xludf.DUMMYFUNCTION("""COMPUTED_VALUE"""),600.0) -> 600 | N2: =IFERROR(__xludf.DUMMYFUNCTION("""COMPUTED_VALUE"""),700.0) -> 700 | O2: =IFERROR(__xludf.DUMMYFUNCTION("""COMPUTED_VALUE"""),800.0) -> 800 | P2: Meet the energy threshold to obtain your desired rank | Q2: Below you will find instructions on how to play our Strafe (Movement scenarios)
A3: Clicking | B3: Dynamic | C3: =IFERROR(__xludf.DUMMYFUNCTION("importrange(""https://docs.google.com/spreadsheets/d/10ck-sXoSgAYeiVI9iaaWwSqxC7KoxNO-2AtO08C-eCw/"", ""Benchmarks!J5:J20"")")," VT Pasu Rasp Intermediate") -> VT Pasu Rasp Intermediate | F3: =IFERROR(__xludf.DUMMYFUNCTION("sparkline( E3 - choose(match(E3, {0, L3:O3}), 0, L3, M3, N3, O3), { ""charttype"", ""bar""; ""max"", choose(match(E3, {0, L3:O3}), L3, M3-L3, N3-M3, O3-N3, 0); ""nan"", ""ignore""; ""color1"", iferror(choose(match(E3, {0, L3:O3}), "&" ""#2FCFC2"", ""#B9F2FF"", ""#85FA85"", ""#EC44CA"", ""#fbc2ea"" )) } ) "),"") | G3: {=trunc(min(Advanced!L$2, max( choose(match(E3, {0, L3-(M3-L3), L3:O3}), 0, Novice!O$2, L$2, M$2, N$2, O$2) + (E3 - choose(match(E3, {0, L3-(M3-L3), L3:O3}), 0, L3-(M3-L3), L3, M3, N3, O3)) / choose(match(E3, {0, L3-(M3-L3), L3:O3}), L3-(M3-L3), M3-L3, M3-L3, N3-M3, O3-N3, O3-N3) * choose(match(E3, {0, L3-(M3-L3), L3:O3}), Novice!O$2, L$2-Novice!O$2, M$2-L$2, N$2-M$2, O$2-N$2, O$2-N$2), choose(match(E4, {0, L4-(M4-L4), L4:O4}), 0, Novice!O$2, L$2, M$2, N$2, O$2) + (E4 - choose(match(E4, {0, L4-(M4-L4), L4:O4}), 0, L4-(M4-L4), L4, M4, N4, O4)) / choose(match(E4, {0, L4-(M4-L4), L4:O4}), L4-(M4-L4), M4-L4, M4-L4, N4-M4, O4-N4, O4-N4) * choose(match(E4, {0, L4-(M4-L4), L4:O4}), Novice!O$2, L$2-Novice!O$2, M$2-L$2, N$2-M$2, O$2-N$2, O$2-N$2) )))} -> 0 | I3: ='Average Input'!D21 | J3: =IFERROR(__xludf.DUMMYFUNCTION("sparkline( I3 - choose(match(I3, {0, L3:O3}), 0, L3, M3, N3, O3), { ""charttype"", ""bar""; ""max"", choose(match(I3, {0, L3:O3}), L3, M3-L3, N3-M3, O3-N3, 0); ""nan"", ""ignore""; ""color1"", iferror(choose(match(I3, {0, L3:O3}), "&" ""#2FCFC2"", ""#B9F2FF"", ""#85FA85"", ""#EC44CA"", ""#fbc2ea"" )) } ) "),"") | K3: {=trunc(min( Advanced!L$2, max( choose(match(I3, {0, L3-(M3-L3), L3:O3}), 0, Novice!O$2, L$2, M$2, N$2, O$2) + (I3 - choose(match(I3, {0, L3-(M3-L3), L3:O3}), 0, L3-(M3-L3), L3, M3, N3, O3)) / choose(match(I3, {0, L3-(M3-L3), L3:O3}), L3-(M3-L3), M3-L3, M3-L3, N3-M3, O3-N3, O3-N3) * choose(match(I3, {0, L3-(M3-L3), L3:O3}), Novice!O$2, L$2-Novice!O$2, M$2-L$2, N$2-M$2, O$2-N$2, O$2-N$2), choose(match(I4, {0, L4-(M4-L4), L4:O4}), 0, Novice!O$2, L$2, M$2, N$2, O$2) + (I4 - choose(match(I4, {0, L4-(M4-L4), L4:O4}), 0, L4-(M4-L4), L4, M4, N4, O4)) / choose(match(I4, {0, L4-(M4-L4), L4:O4}), L4-(M4-L4), M4-L4, M4-L4, N4-M4, O4-N4, O4-N4) * choose(match(I4, {0, L4-(M4-L4), L4:O4}), Novice!O$2, L$2-Novice!O$2, M$2-L$2, N$2-M$2, O$2-N$2, O$2-N$2) )))} -> 0 | L3: =IFERROR(__xludf.DUMMYFUNCTION("""COMPUTED_VALUE"""),750.0) -> 750 | M3: =IFERROR(__xludf.DUMMYFUNCTION("""COMPUTED_VALUE"""),850.0) -> 850 | N3: =IFERROR(__xludf.DUMMYFUNCTION("""COMPUTED_VALUE"""),950.0) -> 950 | O3: =IFERROR(__xludf.DUMMYFUNCTION("""COMPUTED_VALUE"""),1050.0) -> 1050 | P3: Each subcategory awards points based on your highest achieved rank threshold | Q3: VT ArcStrafe, VT AngleStrafe, VT AirStrafe
C4: =IFERROR(__xludf.DUMMYFUNCTION("""COMPUTED_VALUE""")," VT Bounceshot Intermediate") -> VT Bounceshot Intermediate | F4: =IFERROR(__xludf.DUMMYFUNCTION("sparkline( E4 - choose(match(E4, {0, L4:O4}), 0, L4, M4, N4, O4), { ""charttype"", ""bar""; ""max"", choose(match(E4, {0, L4:O4}), L4, M4-L4, N4-M4, O4-N4, 0); ""nan"", ""ignore""; ""color1"", iferror(choose(match(E4, {0, L4:O4}), "&" ""#2FCFC2"", ""#B9F2FF"", ""#85FA85"", ""#EC44CA"", ""#fbc2ea"" )) } ) "),"") | I4: ='Average Input'!D22 | J4: =IFERROR(__xludf.DUMMYFUNCTION("sparkline( I4 - choose(match(I4, {0, L4:O4}), 0, L4, M4, N4, O4), { ""charttype"", ""bar""; ""max"", choose(match(I4, {0, L4:O4}), L4, M4-L4, N4-M4, O4-N4, 0); ""nan"", ""ignore""; ""color1"", iferror(choose(match(I4, {0, L4:O4}), "&" ""#2FCFC2"", ""#B9F2FF"", ""#85FA85"", ""#EC44CA"", ""#fbc2ea"" )) } ) "),"") | L4: =IFERROR(__xludf.DUMMYFUNCTION("""COMPUTED_VALUE"""),600.0) -> 600 | M4: =IFERROR(__xludf.DUMMYFUNCTION("""COMPUTED_VALUE"""),700.0) -> 700 | N4: =IFERROR(__xludf.DUMMYFUNCTION("""COMPUTED_VALUE"""),800.0) -> 800 | O4: =IFERROR(__xludf.DUMMYFUNCTION("""COMPUTED_VALUE"""),900.0) -> 900 | Q4: In these three scenarios above, MBS scoring is used - by default you should see a bar that fills up as you move. The amount of movement score you get is based on the time spent strafing before changing direction. As long as you change direction while the bar is green, you get maximum movement score. The bar is green between 3% and 100% fill. If you keep moving while the bar is full, you don't get any score. The score is capped to a value that is easy to reach (200 for AngleStrafe & ArcStrafe 1000 for AirStrafe) as long as you move throughout the scenario. You should find ways to move in ways that makes aiming easy.
B5: Static | C5: =IFERROR(__xludf.DUMMYFUNCTION("""COMPUTED_VALUE""")," VT 1w5ts Rasp Intermediate") -> VT 1w5ts Rasp Intermediate | F5: =IFERROR(__xludf.DUMMYFUNCTION("sparkline( E5 - choose(match(E5, {0, L5:O5}), 0, L5, M5, N5, O5), { ""charttype"", ""bar""; ""max"", choose(match(E5, {0, L5:O5}), L5, M5-L5, N5-M5, O5-N5, 0); ""nan"", ""ignore""; ""color1"", iferror(choose(match(E5, {0, L5:O5}), "&" ""#2FCFC2"", ""#B9F2FF"", ""#85FA85"", ""#EC44CA"", ""#fbc2ea"" )) } ) "),"") | G5: {=trunc(min(Advanced!L$2, max( choose(match(E5, {0, L5-(M5-L5), L5:O5}), 0, Novice!O$2, L$2, M$2, N$2, O$2) + (E5 - choose(match(E5, {0, L5-(M5-L5), L5:O5}), 0, L5-(M5-L5), L5, M5, N5, O5)) / choose(match(E5, {0, L5-(M5-L5), L5:O5}), L5-(M5-L5), M5-L5, M5-L5, N5-M5, O5-N5, O5-N5) * choose(match(E5, {0, L5-(M5-L5), L5:O5}), Novice!O$2, L$2-Novice!O$2, M$2-L$2, N$2-M$2, O$2-N$2, O$2-N$2), choose(match(E6, {0, L6-(M6-L6), L6:O6}), 0, Novice!O$2, L$2, M$2, N$2, O$2) + (E6 - choose(match(E6, {0, L6-(M6-L6), L6:O6}), 0, L6-(M6-L6), L6, M6, N6, O6)) / choose(match(E6, {0, L6-(M6-L6), L6:O6}), L6-(M6-L6), M6-L6, M6-L6, N6-M6, O6-N6, O6-N6) * choose(match(E6, {0, L6-(M6-L6), L6:O6}), Novice!O$2, L$2-Novice!O$2, M$2-L$2, N$2-M$2, O$2-N$2, O$2-N$2) )))} -> 0 | I5: ='Average Input'!D23 | J5: =IFERROR(__xludf.DUMMYFUNCTION("sparkline( I5 - choose(match(I5, {0, L5:O5}), 0, L5, M5, N5, O5), { ""charttype"", ""bar""; ""max"", choose(match(I5, {0, L5:O5}), L5, M5-L5, N5-M5, O5-N5, 0); ""nan"", ""ignore""; ""color1"", iferror(choose(match(I5, {0, L5:O5}), "&" ""#2FCFC2"", ""#B9F2FF"", ""#85FA85"", ""#EC44CA"", ""#fbc2ea"" )) } ) "),"") | K5: {=trunc(min( Advanced!L$2, max( choose(match(I5, {0, L5-(M5-L5), L5:O5}), 0, Novice!O$2, L$2, M$2, N$2, O$2) + (I5 - choose(match(I5, {0, L5-(M5-L5), L5:O5}), 0, L5-(M5-L5), L5, M5, N5, O5)) / choose(match(I5, {0, L5-(M5-L5), L5:O5}), L5-(M5-L5), M5-L5, M5-L5, N5-M5, O5-N5, O5-N5) * choose(match(I5, {0, L5-(M5-L5), L5:O5}), Novice!O$2, L$2-Novice!O$2, M$2-L$2, N$2-M$2, O$2-N$2, O$2-N$2), choose(match(I6, {0, L6-(M6-L6), L6:O6}), 0, Novice!O$2, L$2, M$2, N$2, O$2) + (I6 - choose(match(I6, {0, L6-(M6-L6), L6:O6}), 0, L6-(M6-L6), L6, M6, N6, O6)) / choose(match(I6, {0, L6-(M6-L6), L6:O6}), L6-(M6-L6), M6-L6, M6-L6, N6-M6, O6-N6, O6-N6) * choose(match(I6, {0, L6-(M6-L6), L6:O6}), Novice!O$2, L$2-Novice!O$2, M$2-L$2, N$2-M$2, O$2-N$2, O$2-N$2) )))} -> 0 | L5: =IFERROR(__xludf.DUMMYFUNCTION("""COMPUTED_VALUE"""),1000.0) -> 1000 | M5: =IFERROR(__xludf.DUMMYFUNCTION("""COMPUTED_VALUE"""),1100.0) -> 1100 | N5: =IFERROR(__xludf.DUMMYFUNCTION("""COMPUTED_VALUE"""),1200.0) -> 1200 | O5: =IFERROR(__xludf.DUMMYFUNCTION("""COMPUTED_VALUE"""),1300.0) -> 1300 | P5: Only one score from each subcategory counts
C6: =IFERROR(__xludf.DUMMYFUNCTION("""COMPUTED_VALUE""")," VT Multiclick 120 Intermediate") -> VT Multiclick 120 Intermediate | F6: =IFERROR(__xludf.DUMMYFUNCTION("sparkline( E6 - choose(match(E6, {0, L6:O6}), 0, L6, M6, N6, O6), { ""charttype"", ""bar""; ""max"", choose(match(E6, {0, L6:O6}), L6, M6-L6, N6-M6, O6-N6, 0); ""nan"", ""ignore""; ""color1"", iferror(choose(match(E6, {0, L6:O6}), "&" ""#2FCFC2"", ""#B9F2FF"", ""#85FA85"", ""#EC44CA"", ""#fbc2ea"" )) } ) "),"") | I6: ='Average Input'!D24 | J6: =IFERROR(__xludf.DUMMYFUNCTION("sparkline( I6 - choose(match(I6, {0, L6:O6}), 0, L6, M6, N6, O6), { ""charttype"", ""bar""; ""max"", choose(match(I6, {0, L6:O6}), L6, M6-L6, N6-M6, O6-N6, 0); ""nan"", ""ignore""; ""color1"", iferror(choose(match(I6, {0, L6:O6}), "&" ""#2FCFC2"", ""#B9F2FF"", ""#85FA85"", ""#EC44CA"", ""#fbc2ea"" )) } ) "),"") | L6: =IFERROR(__xludf.DUMMYFUNCTION("""COMPUTED_VALUE"""),1360.0) -> 1360 | M6: =IFERROR(__xludf.DUMMYFUNCTION("""COMPUTED_VALUE"""),1460.0) -> 1460 | N6: =IFERROR(__xludf.DUMMYFUNCTION("""COMPUTED_VALUE"""),1560.0) -> 1560 | O6: =IFERROR(__xludf.DUMMYFUNCTION("""COMPUTED_VALUE"""),1660.0) -> 1660
B7: Strafe | C7: =IFERROR(__xludf.DUMMYFUNCTION("""COMPUTED_VALUE""")," VT AngleStrafe Intermediate") -> VT AngleStrafe Intermediate | F7: =IFERROR(__xludf.DUMMYFUNCTION("sparkline( E7 - choose(match(E7, {0, L7:O7}), 0, L7, M7, N7, O7), { ""charttype"", ""bar""; ""max"", choose(match(E7, {0, L7:O7}), L7, M7-L7, N7-M7, O7-N7, 0); ""nan"", ""ignore""; ""color1"", iferror(choose(match(E7, {0, L7:O7}), "&" ""#2FCFC2"", ""#B9F2FF"", ""#85FA85"", ""#EC44CA"", ""#fbc2ea"" )) } ) "),"") | I7: ='Average Input'!D25 | J7: =IFERROR(__xludf.DUMMYFUNCTION("sparkline( I7 - choose(match(I7, {0, L7:O7}), 0, L7, M7, N7, O7), { ""charttype"", ""bar""; ""max"", choose(match(I7, {0, L7:O7}), L7, M7-L7, N7-M7, O7-N7, 0); ""nan"", ""ignore""; ""color1"", iferror(choose(match(I7, {0, L7:O7}), "&" ""#2FCFC2"", ""#B9F2FF"", ""#85FA85"", ""#EC44CA"", ""#fbc2ea"" )) } ) "),"") | L7: =IFERROR(__xludf.DUMMYFUNCTION("""COMPUTED_VALUE"""),740.0) -> 740 | M7: =IFERROR(__xludf.DUMMYFUNCTION("""COMPUTED_VALUE"""),830.0) -> 830 | N7: =IFERROR(__xludf.DUMMYFUNCTION("""COMPUTED_VALUE"""),920.0) -> 920 | O7: =IFERROR(__xludf.DUMMYFUNCTION("""COMPUTED_VALUE"""),1000.0) -> 1000 | P7: Strafe scenarios will not count towards your rank, but are required to acquire Complete roles
C8: =IFERROR(__xludf.DUMMYFUNCTION("""COMPUTED_VALUE""")," VT ArcStrafe Intermediate") -> VT ArcStrafe Intermediate | F8: =IFERROR(__xludf.DUMMYFUNCTION("sparkline( E8 - choose(match(E8, {0, L8:O8}), 0, L8, M8, N8, O8), { ""charttype"", ""bar""; ""max"", choose(match(E8, {0, L8:O8}), L8, M8-L8, N8-M8, O8-N8, 0); ""nan"", ""ignore""; ""color1"", iferror(choose(match(E8, {0, L8:O8}), "&" ""#2FCFC2"", ""#B9F2FF"", ""#85FA85"", ""#EC44CA"", ""#fbc2ea"" )) } ) "),"") | I8: ='Average Input'!D26 | J8: =IFERROR(__xludf.DUMMYFUNCTION("sparkline( I8 - choose(match(I8, {0, L8:O8}), 0, L8, M8, N8, O8), { ""charttype"", ""bar""; ""max"", choose(match(I8, {0, L8:O8}), L8, M8-L8, N8-M8, O8-N8, 0); ""nan"", ""ignore""; ""color1"", iferror(choose(match(I8, {0, L8:O8}), "&" ""#2FCFC2"", ""#B9F2FF"", ""#85FA85"", ""#EC44CA"", ""#fbc2ea"" )) } ) "),"") | L8: =IFERROR(__xludf.DUMMYFUNCTION("""COMPUTED_VALUE"""),660.0) -> 660 | M8: =IFERROR(__xludf.DUMMYFUNCTION("""COMPUTED_VALUE"""),750.0) -> 750 | N8: =IFERROR(__xludf.DUMMYFUNCTION("""COMPUTED_VALUE"""),850.0) -> 850 | O8: =IFERROR(__xludf.DUMMYFUNCTION("""COMPUTED_VALUE"""),940.0) -> 940
A9: Tracking | B9: Precise | C9: =IFERROR(__xludf.DUMMYFUNCTION("""COMPUTED_VALUE""")," VT Smoothbot Intermediate") -> VT Smoothbot Intermediate | F9: =IFERROR(__xludf.DUMMYFUNCTION("sparkline( E9 - choose(match(E9, {0, L9:O9}), 0, L9, M9, N9, O9), { ""charttype"", ""bar""; ""max"", choose(match(E9, {0, L9:O9}), L9, M9-L9, N9-M9, O9-N9, 0); ""nan"", ""ignore""; ""color1"", iferror(choose(match(E9, {0, L9:O9}), "&" ""#2FCFC2"", ""#B9F2FF"", ""#85FA85"", ""#EC44CA"", ""#fbc2ea"" )) } ) "),"") | G9: {=trunc(min(Advanced!L$2, max( choose(match(E9, {0, L9-(M9-L9), L9:O9}), 0, Novice!O$2, L$2, M$2, N$2, O$2) + (E9 - choose(match(E9, {0, L9-(M9-L9), L9:O9}), 0, L9-(M9-L9), L9, M9, N9, O9)) / choose(match(E9, {0, L9-(M9-L9), L9:O9}), L9-(M9-L9), M9-L9, M9-L9, N9-M9, O9-N9, O9-N9) * choose(match(E9, {0, L9-(M9-L9), L9:O9}), Novice!O$2, L$2-Novice!O$2, M$2-L$2, N$2-M$2, O$2-N$2, O$2-N$2), choose(match(E10, {0, L10-(M10-L10), L10:O10}), 0, Novice!O$2, L$2, M$2, N$2, O$2) + (E10 - choose(match(E10, {0, L10-(M10-L10), L10:O10}), 0, L10-(M10-L10), L10, M10, N10, O10)) / choose(match(E10, {0, L10-(M10-L10), L10:O10}), L10-(M10-L10), M10-L10, M10-L10, N10-M10, O10-N10, O10-N10) * choose(match(E10, {0, L10-(M10-L10), L10:O10}), Novice!O$2, L$2-Novice!O$2, M$2-L$2, N$2-M$2, O$2-N$2, O$2-N$2) )))} -> 0 | I9: ='Average Input'!D27 | J9: =IFERROR(__xludf.DUMMYFUNCTION("sparkline( I9 - choose(match(I9, {0, L9:O9}), 0, L9, M9, N9, O9), { ""charttype"", ""bar""; ""max"", choose(match(I9, {0, L9:O9}), L9, M9-L9, N9-M9, O9-N9, 0); ""nan"", ""ignore""; ""color1"", iferror(choose(match(I9, {0, L9:O9}), "&" ""#2FCFC2"", ""#B9F2FF"", ""#85FA85"", ""#EC44CA"", ""#fbc2ea"" )) } ) "),"") | K9: {=trunc(min( Advanced!L$2, max( choose(match(I9, {0, L9-(M9-L9), L9:O9}), 0, Novice!O$2, L$2, M$2, N$2, O$2) + (I9 - choose(match(I9, {0, L9-(M9-L9), L9:O9}), 0, L9-(M9-L9), L9, M9, N9, O9)) / choose(match(I9, {0, L9-(M9-L9), L9:O9}), L9-(M9-L9), M9-L9, M9-L9, N9-M9, O9-N9, O9-N9) * choose(match(I9, {0, L9-(M9-L9), L9:O9}), Novice!O$2, L$2-Novice!O$2, M$2-L$2, N$2-M$2, O$2-N$2, O$2-N$2), choose(match(I10, {0, L10-(M10-L10), L10:O10}), 0, Novice!O$2, L$2, M$2, N$2, O$2) + (I10 - choose(match(I10, {0, L10-(M10-L10), L10:O10}), 0, L10-(M10-L10), L10, M10, N10, O10)) / choose(match(I10, {0, L10-(M10-L10), L10:O10}), L10-(M10-L10), M10-L10, M10-L10, N10-M10, O10-N10, O10-N10) * choose(match(I10, {0, L10-(M10-L10), L10:O10}), Novice!O$2, L$2-Novice!O$2, M$2-L$2, N$2-M$2, O$2-N$2, O$2-N$2) )))} -> 0 | L9: =IFERROR(__xludf.DUMMYFUNCTION("""COMPUTED_VALUE"""),3050.0) -> 3050 | M9: =IFERROR(__xludf.DUMMYFUNCTION("""COMPUTED_VALUE"""),3450.0) -> 3450 | N9: =IFERROR(__xludf.DUMMYFUNCTION("""COMPUTED_VALUE"""),3850.0) -> 3850 | O9: =IFERROR(__xludf.DUMMYFUNCTION("""COMPUTED_VALUE"""),4250.0) -> 4250 | P9: All your energy combined defines your final rank
C10: =IFERROR(__xludf.DUMMYFUNCTION("""COMPUTED_VALUE""")," VT PreciseOrb Intermediate") -> VT PreciseOrb Intermediate | F10: =IFERROR(__xludf.DUMMYFUNCTION("sparkline( E10 - choose(match(E10, {0, L10:O10}), 0, L10, M10, N10, O10), { ""charttype"", ""bar""; ""max"", choose(match(E10, {0, L10:O10}), L10, M10-L10, N10-M10, O10-N10, 0); ""nan"", ""ignore""; ""color1"", iferror(choose(match(E10"&", {0, L10:O10}), ""#2FCFC2"", ""#B9F2FF"", ""#85FA85"", ""#EC44CA"", ""#fbc2ea"" )) } ) "),"") | I10: ='Average Input'!D28 | J10: =IFERROR(__xludf.DUMMYFUNCTION("sparkline( I10 - choose(match(I10, {0, L10:O10}), 0, L10, M10, N10, O10), { ""charttype"", ""bar""; ""max"", choose(match(I10, {0, L10:O10}), L10, M10-L10, N10-M10, O10-N10, 0); ""nan"", ""ignore""; ""color1"", iferror(choose(match(I10"&", {0, L10:O10}), ""#2FCFC2"", ""#B9F2FF"", ""#85FA85"", ""#EC44CA"", ""#fbc2ea"" )) } ) "),"") | L10: =IFERROR(__xludf.DUMMYFUNCTION("""COMPUTED_VALUE"""),1650.0) -> 1650 | M10: =IFERROR(__xludf.DUMMYFUNCTION("""COMPUTED_VALUE"""),2050.0) -> 2050 | N10: =IFERROR(__xludf.DUMMYFUNCTION("""COMPUTED_VALUE"""),2450.0) -> 2450 | O10: =IFERROR(__xludf.DUMMYFUNCTION("""COMPUTED_VALUE"""),2850.0) -> 2850
B11: Reactive | C11: =IFERROR(__xludf.DUMMYFUNCTION("""COMPUTED_VALUE""")," VT Plaza Intermediate") -> VT Plaza Intermediate | F11: =IFERROR(__xludf.DUMMYFUNCTION("sparkline( E11 - choose(match(E11, {0, L11:O11}), 0, L11, M11, N11, O11), { ""charttype"", ""bar""; ""max"", choose(match(E11, {0, L11:O11}), L11, M11-L11, N11-M11, O11-N11, 0); ""nan"", ""ignore""; ""color1"", iferror(choose(match(E11"&", {0, L11:O11}), ""#2FCFC2"", ""#B9F2FF"", ""#85FA85"", ""#EC44CA"", ""#fbc2ea"" )) } ) "),"") | G11: {=trunc(min(Advanced!L$2, max( choose(match(E11, {0, L11-(M11-L11), L11:O11}), 0, Novice!O$2, L$2, M$2, N$2, O$2) + (E11 - choose(match(E11, {0, L11-(M11-L11), L11:O11}), 0, L11-(M11-L11), L11, M11, N11, O11)) / choose(match(E11, {0, L11-(M11-L11), L11:O11}), L11-(M11-L11), M11-L11, M11-L11, N11-M11, O11-N11, O11-N11) * choose(match(E11, {0, L11-(M11-L11), L11:O11}), Novice!O$2, L$2-Novice!O$2, M$2-L$2, N$2-M$2, O$2-N$2, O$2-N$2), choose(match(E12, {0, L12-(M12-L12), L12:O12}), 0, Novice!O$2, L$2, M$2, N$2, O$2) + (E12 - choose(match(E12, {0, L12-(M12-L12), L12:O12}), 0, L12-(M12-L12), L12, M12, N12, O12)) / choose(match(E12, {0, L12-(M12-L12), L12:O12}), L12-(M12-L12), M12-L12, M12-L12, N12-M12, O12-N12, O12-N12) * choose(match(E12, {0, L12-(M12-L12), L12:O12}), Novice!O$2, L$2-Novice!O$2, M$2-L$2, N$2-M$2, O$2-N$2, O$2-N$2) )))} -> 0 | I11: ='Average Input'!D29 | J11: =IFERROR(__xludf.DUMMYFUNCTION("sparkline( I11 - choose(match(I11, {0, L11:O11}), 0, L11, M11, N11, O11), { ""charttype"", ""bar""; ""max"", choose(match(I11, {0, L11:O11}), L11, M11-L11, N11-M11, O11-N11, 0); ""nan"", ""ignore""; ""color1"", iferror(choose(match(I11"&", {0, L11:O11}), ""#2FCFC2"", ""#B9F2FF"", ""#85FA85"", ""#EC44CA"", ""#fbc2ea"" )) } ) "),"") | K11: {=trunc(min( Advanced!L$2, max( choose(match(I11, {0, L11-(M11-L11), L11:O11}), 0, Novice!O$2, L$2, M$2, N$2, O$2) + (I11 - choose(match(I11, {0, L11-(M11-L11), L11:O11}), 0, L11-(M11-L11), L11, M11, N11, O11)) / choose(match(I11, {0, L11-(M11-L11), L11:O11}), L11-(M11-L11), M11-L11, M11-L11, N11-M11, O11-N11, O11-N11) * choose(match(I11, {0, L11-(M11-L11), L11:O11}), Novice!O$2, L$2-Novice!O$2, M$2-L$2, N$2-M$2, O$2-N$2, O$2-N$2), choose(match(I12, {0, L12-(M12-L12), L12:O12}), 0, Novice!O$2, L$2, M$2, N$2, O$2) + (I12 - choose(match(I12, {0, L12-(M12-L12), L12:O12}), 0, L12-(M12-L12), L12, M12, N12, O12)) / choose(match(I12, {0, L12-(M12-L12), L12:O12}), L12-(M12-L12), M12-L12, M12-L12, N12-M12, O12-N12, O12-N12) * choose(match(I12, {0, L12-(M12-L12), L12:O12}), Novice!O$2, L$2-Novice!O$2, M$2-L$2, N$2-M$2, O$2-N$2, O$2-N$2) )))} -> 0 | L11: =IFERROR(__xludf.DUMMYFUNCTION("""COMPUTED_VALUE"""),2680.0) -> 2680 | M11: =IFERROR(__xludf.DUMMYFUNCTION("""COMPUTED_VALUE"""),2980.0) -> 2980 | N11: =IFERROR(__xludf.DUMMYFUNCTION("""COMPUTED_VALUE"""),3280.0) -> 3280 | O11: =IFERROR(__xludf.DUMMYFUNCTION("""COMPUTED_VALUE"""),3530.0) -> 3530 | P11: Pushing your score further awards more Energy
C12: =IFERROR(__xludf.DUMMYFUNCTION("""COMPUTED_VALUE""")," VT Air Intermediate") -> VT Air Intermediate | F12: =IFERROR(__xludf.DUMMYFUNCTION("sparkline( E12 - choose(match(E12, {0, L12:O12}), 0, L12, M12, N12, O12), { ""charttype"", ""bar""; ""max"", choose(match(E12, {0, L12:O12}), L12, M12-L12, N12-M12, O12-N12, 0); ""nan"", ""ignore""; ""color1"", iferror(choose(match(E12"&", {0, L12:O12}), ""#2FCFC2"", ""#B9F2FF"", ""#85FA85"", ""#EC44CA"", ""#fbc2ea"" )) } ) "),"") | I12: ='Average Input'!D30 | J12: =IFERROR(__xludf.DUMMYFUNCTION("sparkline( I12 - choose(match(I12, {0, L12:O12}), 0, L12, M12, N12, O12), { ""charttype"", ""bar""; ""max"", choose(match(I12, {0, L12:O12}), L12, M12-L12, N12-M12, O12-N12, 0); ""nan"", ""ignore""; ""color1"", iferror(choose(match(I12"&", {0, L12:O12}), ""#2FCFC2"", ""#B9F2FF"", ""#85FA85"", ""#EC44CA"", ""#fbc2ea"" )) } ) "),"") | L12: =IFERROR(__xludf.DUMMYFUNCTION("""COMPUTED_VALUE"""),2450.0) -> 2450 | M12: =IFERROR(__xludf.DUMMYFUNCTION("""COMPUTED_VALUE"""),2700.0) -> 2700 | N12: =IFERROR(__xludf.DUMMYFUNCTION("""COMPUTED_VALUE"""),2950.0) -> 2950 | O12: =IFERROR(__xludf.DUMMYFUNCTION("""COMPUTED_VALUE"""),3200.0) -> 3200 | Q12: VT PatStrafe
B13: Strafe | C13: =IFERROR(__xludf.DUMMYFUNCTION("""COMPUTED_VALUE""")," VT PatStrafe Intermediate") -> VT PatStrafe Intermediate | F13: =IFERROR(__xludf.DUMMYFUNCTION("sparkline( E13 - choose(match(E13, {0, L13:O13}), 0, L13, M13, N13, O13), { ""charttype"", ""bar""; ""max"", choose(match(E13, {0, L13:O13}), L13, M13-L13, N13-M13, O13-N13, 0); ""nan"", ""ignore""; ""color1"", iferror(choose(match(E13"&", {0, L13:O13}), ""#2FCFC2"", ""#B9F2FF"", ""#85FA85"", ""#EC44CA"", ""#fbc2ea"" )) } ) "),"") | I13: ='Average Input'!D31 | J13: =IFERROR(__xludf.DUMMYFUNCTION("sparkline( I13 - choose(match(I13, {0, L13:O13}), 0, L13, M13, N13, O13), { ""charttype"", ""bar""; ""max"", choose(match(I13, {0, L13:O13}), L13, M13-L13, N13-M13, O13-N13, 0); ""nan"", ""ignore""; ""color1"", iferror(choose(match(I13"&", {0, L13:O13}), ""#2FCFC2"", ""#B9F2FF"", ""#85FA85"", ""#EC44CA"", ""#fbc2ea"" )) } ) "),"") | L13: =IFERROR(__xludf.DUMMYFUNCTION("""COMPUTED_VALUE"""),2260.0) -> 2260 | M13: =IFERROR(__xludf.DUMMYFUNCTION("""COMPUTED_VALUE"""),2620.0) -> 2620 | N13: =IFERROR(__xludf.DUMMYFUNCTION("""COMPUTED_VALUE"""),2800.0) -> 2800 | O13: =IFERROR(__xludf.DUMMYFUNCTION("""COMPUTED_VALUE"""),3050.0) -> 3050 | P13: Strafe scenarios will not count towards your rank, but are required to acquire Complete roles | Q13: In the scenario above, conditional distance travelled scoring is used and is capped to 1000. In short, as long as you don't mirror every bot 100% of the time, you will reach the score cap. In theory, reaching maximum movement score requires you to anti-mirror for at least about 30-40% of the time. In practice you will get anti-mirror score while you unintentionally anti-mirror anyway. If you only mirror during the run, you will not reach the movement score cap. If you only anti-mirror you will easily reach score cap but your accuracy will suffer. You should mix up your movement and focus on accuracy.
C14: =IFERROR(__xludf.DUMMYFUNCTION("""COMPUTED_VALUE""")," VT AirStrafe Intermediate") -> VT AirStrafe Intermediate | F14: =IFERROR(__xludf.DUMMYFUNCTION("sparkline( E14 - choose(match(E14, {0, L14:O14}), 0, L14, M14, N14, O14), { ""charttype"", ""bar""; ""max"", choose(match(E14, {0, L14:O14}), L14, M14-L14, N14-M14, O14-N14, 0); ""nan"", ""ignore""; ""color1"", iferror(choose(match(E14"&", {0, L14:O14}), ""#2FCFC2"", ""#B9F2FF"", ""#85FA85"", ""#EC44CA"", ""#fbc2ea"" )) } ) "),"") | I14: ='Average Input'!D32 | J14: =IFERROR(__xludf.DUMMYFUNCTION("sparkline( I14 - choose(match(I14, {0, L14:O14}), 0, L14, M14, N14, O14), { ""charttype"", ""bar""; ""max"", choose(match(I14, {0, L14:O14}), L14, M14-L14, N14-M14, O14-N14, 0); ""nan"", ""ignore""; ""color1"", iferror(choose(match(I14"&", {0, L14:O14}), ""#2FCFC2"", ""#B9F2FF"", ""#85FA85"", ""#EC44CA"", ""#fbc2ea"" )) } ) "),"") | L14: =IFERROR(__xludf.DUMMYFUNCTION("""COMPUTED_VALUE"""),2800.0) -> 2800 | M14: =IFERROR(__xludf.DUMMYFUNCTION("""COMPUTED_VALUE"""),3000.0) -> 3000 | N14: =IFERROR(__xludf.DUMMYFUNCTION("""COMPUTED_VALUE"""),3200.0) -> 3200 | O14: =IFERROR(__xludf.DUMMYFUNCTION("""COMPUTED_VALUE"""),3400.0) -> 3400
A15: Switching | B15: Speed | C15: =IFERROR(__xludf.DUMMYFUNCTION("""COMPUTED_VALUE""")," VT psalmTS Intermediate") -> VT psalmTS Intermediate | F15: =IFERROR(__xludf.DUMMYFUNCTION("sparkline( E15 - choose(match(E15, {0, L15:O15}), 0, L15, M15, N15, O15), { ""charttype"", ""bar""; ""max"", choose(match(E15, {0, L15:O15}), L15, M15-L15, N15-M15, O15-N15, 0); ""nan"", ""ignore""; ""color1"", iferror(choose(match(E15"&", {0, L15:O15}), ""#2FCFC2"", ""#B9F2FF"", ""#85FA85"", ""#EC44CA"", ""#fbc2ea"" )) } ) "),"") | G15: {=trunc(min(Advanced!L$2, max( choose(match(E15, {0, L15-(M15-L15), L15:O15}), 0, Novice!O$2, L$2, M$2, N$2, O$2) + (E15 - choose(match(E15, {0, L15-(M15-L15), L15:O15}), 0, L15-(M15-L15), L15, M15, N15, O15)) / choose(match(E15, {0, L15-(M15-L15), L15:O15}), L15-(M15-L15), M15-L15, M15-L15, N15-M15, O15-N15, O15-N15) * choose(match(E15, {0, L15-(M15-L15), L15:O15}), Novice!O$2, L$2-Novice!O$2, M$2-L$2, N$2-M$2, O$2-N$2, O$2-N$2), choose(match(E16, {0, L16-(M16-L16), L16:O16}), 0, Novice!O$2, L$2, M$2, N$2, O$2) + (E16 - choose(match(E16, {0, L16-(M16-L16), L16:O16}), 0, L16-(M16-L16), L16, M16, N16, O16)) / choose(match(E16, {0, L16-(M16-L16), L16:O16}), L16-(M16-L16), M16-L16, M16-L16, N16-M16, O16-N16, O16-N16) * choose(match(E16, {0, L16-(M16-L16), L16:O16}), Novice!O$2, L$2-Novice!O$2, M$2-L$2, N$2-M$2, O$2-N$2, O$2-N$2) )))} -> 0 | I15: ='Average Input'!D33 | J15: =IFERROR(__xludf.DUMMYFUNCTION("sparkline( I15 - choose(match(I15, {0, L15:O15}), 0, L15, M15, N15, O15), { ""charttype"", ""bar""; ""max"", choose(match(I15, {0, L15:O15}), L15, M15-L15, N15-M15, O15-N15, 0); ""nan"", ""ignore""; ""color1"", iferror(choose(match(I15"&", {0, L15:O15}), ""#2FCFC2"", ""#B9F2FF"", ""#85FA85"", ""#EC44CA"", ""#fbc2ea"" )) } ) "),"") | K15: {=trunc(min( Advanced!L$2, max( choose(match(I15, {0, L15-(M15-L15), L15:O15}), 0, Novice!O$2, L$2, M$2, N$2, O$2) + (I15 - choose(match(I15, {0, L15-(M15-L15), L15:O15}), 0, L15-(M15-L15), L15, M15, N15, O15)) / choose(match(I15, {0, L15-(M15-L15), L15:O15}), L15-(M15-L15), M15-L15, M15-L15, N15-M15, O15-N15, O15-N15) * choose(match(I15, {0, L15-(M15-L15), L15:O15}), Novice!O$2, L$2-Novice!O$2, M$2-L$2, N$2-M$2, O$2-N$2, O$2-N$2), choose(match(I16, {0, L16-(M16-L16), L16:O16}), 0, Novice!O$2, L$2, M$2, N$2, O$2) + (I16 - choose(match(I16, {0, L16-(M16-L16), L16:O16}), 0, L16-(M16-L16), L16, M16, N16, O16)) / choose(match(I16, {0, L16-(M16-L16), L16:O16}), L16-(M16-L16), M16-L16, M16-L16, N16-M16, O16-N16, O16-N16) * choose(match(I16, {0, L16-(M16-L16), L16:O16}), Novice!O$2, L$2-Novice!O$2, M$2-L$2, N$2-M$2, O$2-N$2, O$2-N$2) )))} -> 0 | L15: =IFERROR(__xludf.DUMMYFUNCTION("""COMPUTED_VALUE"""),810.0) -> 810 | M15: =IFERROR(__xludf.DUMMYFUNCTION("""COMPUTED_VALUE"""),880.0) -> 880 | N15: =IFERROR(__xludf.DUMMYFUNCTION("""COMPUTED_VALUE"""),950.0) -> 950 | O15: =IFERROR(__xludf.DUMMYFUNCTION("""COMPUTED_VALUE"""),1020.0) -> 1020 | P15: This allows you to obtain ranks without having to be equally good in each subcategory
C16: =IFERROR(__xludf.DUMMYFUNCTION("""COMPUTED_VALUE""")," VT skyTS Intermediate") -> VT skyTS Intermediate | F16: =IFERROR(__xludf.DUMMYFUNCTION("sparkline( E16 - choose(match(E16, {0, L16:O16}), 0, L16, M16, N16, O16), { ""charttype"", ""bar""; ""max"", choose(match(E16, {0, L16:O16}), L16, M16-L16, N16-M16, O16-N16, 0); ""nan"", ""ignore""; ""color1"", iferror(choose(match(E16"&", {0, L16:O16}), ""#2FCFC2"", ""#B9F2FF"", ""#85FA85"", ""#EC44CA"", ""#fbc2ea"" )) } ) "),"") | I16: ='Average Input'!D34 | J16: =IFERROR(__xludf.DUMMYFUNCTION("sparkline( I16 - choose(match(I16, {0, L16:O16}), 0, L16, M16, N16, O16), { ""charttype"", ""bar""; ""max"", choose(match(I16, {0, L16:O16}), L16, M16-L16, N16-M16, O16-N16, 0); ""nan"", ""ignore""; ""color1"", iferror(choose(match(I16"&", {0, L16:O16}), ""#2FCFC2"", ""#B9F2FF"", ""#85FA85"", ""#EC44CA"", ""#fbc2ea"" )) } ) "),"") | L16: =IFERROR(__xludf.DUMMYFUNCTION("""COMPUTED_VALUE"""),1030.0) -> 1030 | M16: =IFERROR(__xludf.DUMMYFUNCTION("""COMPUTED_VALUE"""),1130.0) -> 1130 | N16: =IFERROR(__xludf.DUMMYFUNCTION("""COMPUTED_VALUE"""),1220.0) -> 1220 | O16: =IFERROR(__xludf.DUMMYFUNCTION("""COMPUTED_VALUE"""),1300.0) -> 1300
B17: Evasive | C17: =IFERROR(__xludf.DUMMYFUNCTION("""COMPUTED_VALUE""")," VT evaTS Intermediate") -> VT evaTS Intermediate | F17: =IFERROR(__xludf.DUMMYFUNCTION("sparkline( E17 - choose(match(E17, {0, L17:O17}), 0, L17, M17, N17, O17), { ""charttype"", ""bar""; ""max"", choose(match(E17, {0, L17:O17}), L17, M17-L17, N17-M17, O17-N17, 0); ""nan"", ""ignore""; ""color1"", iferror(choose(match(E17"&", {0, L17:O17}), ""#2FCFC2"", ""#B9F2FF"", ""#85FA85"", ""#EC44CA"", ""#fbc2ea"" )) } ) "),"") | G17: {=trunc(min(Advanced!L$2, max( choose(match(E17, {0, L17-(M17-L17), L17:O17}), 0, Novice!O$2, L$2, M$2, N$2, O$2) + (E17 - choose(match(E17, {0, L17-(M17-L17), L17:O17}), 0, L17-(M17-L17), L17, M17, N17, O17)) / choose(match(E17, {0, L17-(M17-L17), L17:O17}), L17-(M17-L17), M17-L17, M17-L17, N17-M17, O17-N17, O17-N17) * choose(match(E17, {0, L17-(M17-L17), L17:O17}), Novice!O$2, L$2-Novice!O$2, M$2-L$2, N$2-M$2, O$2-N$2, O$2-N$2), choose(match(E18, {0, L18-(M18-L18), L18:O18}), 0, Novice!O$2, L$2, M$2, N$2, O$2) + (E18 - choose(match(E18, {0, L18-(M18-L18), L18:O18}), 0, L18-(M18-L18), L18, M18, N18, O18)) / choose(match(E18, {0, L18-(M18-L18), L18:O18}), L18-(M18-L18), M18-L18, M18-L18, N18-M18, O18-N18, O18-N18) * choose(match(E18, {0, L18-(M18-L18), L18:O18}), Novice!O$2, L$2-Novice!O$2, M$2-L$2, N$2-M$2, O$2-N$2, O$2-N$2) )))} -> 0 | I17: ='Average Input'!D35 | J17: =IFERROR(__xludf.DUMMYFUNCTION("sparkline( I17 - choose(match(I17, {0, L17:O17}), 0, L17, M17, N17, O17), { ""charttype"", ""bar""; ""max"", choose(match(I17, {0, L17:O17}), L17, M17-L17, N17-M17, O17-N17, 0); ""nan"", ""ignore""; ""color1"", iferror(choose(match(I17"&", {0, L17:O17}), ""#2FCFC2"", ""#B9F2FF"", ""#85FA85"", ""#EC44CA"", ""#fbc2ea"" )) } ) "),"") | K17: {=trunc(min( Advanced!L$2, max( choose(match(I17, {0, L17-(M17-L17), L17:O17}), 0, Novice!O$2, L$2, M$2, N$2, O$2) + (I17 - choose(match(I17, {0, L17-(M17-L17), L17:O17}), 0, L17-(M17-L17), L17, M17, N17, O17)) / choose(match(I17, {0, L17-(M17-L17), L17:O17}), L17-(M17-L17), M17-L17, M17-L17, N17-M17, O17-N17, O17-N17) * choose(match(I17, {0, L17-(M17-L17), L17:O17}), Novice!O$2, L$2-Novice!O$2, M$2-L$2, N$2-M$2, O$2-N$2, O$2-N$2), choose(match(I18, {0, L18-(M18-L18), L18:O18}), 0, Novice!O$2, L$2, M$2, N$2, O$2) + (I18 - choose(match(I18, {0, L18-(M18-L18), L18:O18}), 0, L18-(M18-L18), L18, M18, N18, O18)) / choose(match(I18, {0, L18-(M18-L18), L18:O18}), L18-(M18-L18), M18-L18, M18-L18, N18-M18, O18-N18, O18-N18) * choose(match(I18, {0, L18-(M18-L18), L18:O18}), Novice!O$2, L$2-Novice!O$2, M$2-L$2, N$2-M$2, O$2-N$2, O$2-N$2) )))} -> 0 | L17: =IFERROR(__xludf.DUMMYFUNCTION("""COMPUTED_VALUE"""),550.0) -> 550 | M17: =IFERROR(__xludf.DUMMYFUNCTION("""COMPUTED_VALUE"""),600.0) -> 600 | N17: =IFERROR(__xludf.DUMMYFUNCTION("""COMPUTED_VALUE"""),650.0) -> 650 | O17: =IFERROR(__xludf.DUMMYFUNCTION("""COMPUTED_VALUE"""),700.0) -> 700 | P17: Simply search the scenario name in the browser to play the scenarios. Playlists coming soon.
